from collections.abc import Iterable

import pytest

from pyo3_examples import Collatz


def count(gen: Iterable) -> None:
    return sum(1 for _ in gen)


def test_iteration() -> None:
    assert list(Collatz(0)) == [0]
    assert list(Collatz(4)) == [4, 2, 1]
    assert list(Collatz(12)) == [12, 6, 3, 10, 5, 16, 8, 4, 2, 1]
    assert list(Collatz(19)) == [
        19,
        58,
        29,
        88,
        44,
        22,
        11,
        34,
        17,
        52,
        26,
        13,
        40,
        20,
        10,
        5,
        16,
        8,
        4,
        2,
        1,
    ]
    assert count(Collatz(9)) == 20
    assert count(Collatz(27)) == 112
    assert count(Collatz(97)) == 119
    assert count(Collatz(871)) == 179
    assert count(Collatz(989_345_275_647)) == 1349

    # requires an unsigned int (NB pybind11 raises TypeError)
    with pytest.raises(OverflowError):
        Collatz(-1)


def test_control():
    c = Collatz(5)
    assert c.send(12) == 12
    assert next(c) == 6

    c.close()
    with pytest.raises(StopIteration):
        next(c)

    class CustomException(Exception):
        pass

    c = Collatz(12)
    with pytest.raises(StopIteration):
        c.throw()
    with pytest.raises(RuntimeError):
        c.throw(RuntimeError)
    for exception_type in [
        ValueError,
        IndexError,
        KeyError,
        RuntimeError,
        CustomException,
    ]:
        with pytest.raises(exception_type) as e:
            c.throw(exception_type, "testing 123")
        assert "testing 123" in str(
            e.value,
        )  # because KeyError puts quotes around the message
